<mujoco>
	<option gravity="0 0 -59.81" timestep="0.0005"/>
	<worldbody>
        <light diffuse=".5 .5 .5" pos="0 0 3" dir="0 0 -1"/>
		<geom type="plane" size="100 100 0.1" rgba=".9 .9 .9 1"  />
		<body name = "chassis" pos="0 0 4" euler='0 0 0'>
			<joint type="free"/>
			<geom type="cylinder" size="5 0.5" rgba=".9 .9 0 1"/>
			<site name="marker" pos = "0 0 0" size="0.1" />
			<body name="left-tire" pos="0 -4 0" euler='90 0 0'>
				<joint name = "left-wheel" type="hinge" axis="0 0 -1"/>
				<geom type="cylinder" size="1 0.5" rgba="0 .9 0 1"/>
			</body>
			<body name="right-tire" pos="0 4 0" euler='90 0 0'>
				<joint name = "right-wheel" type="hinge" axis="0 0 -1"/>
				<geom type="cylinder" size="1 0.5" rgba="0 .9 0 1"/>
			</body>
		</body>
	</worldbody>
	<sensor>
		<framepos objtype="site" objname="marker"/>
	</sensor>
	<actuator>
		<velocity name="left-velocity" joint="left-wheel" kv="10000"/>
		<velocity name="right-velocity" joint="right-wheel" kv="10000"/>
	</actuator>
</mujoco>
